Workbook

Sheet DEMO_GUIDE
A1: MSH Enhanced Institutional System – Multi‑Term Demo Guide
A3: Purpose: This file contains dummy data across multiple terms (2026) to help you test dashboards, auto-calculated attendance, payments, and reports.
A5: Quick tests:
A6: 1) MASTER_REGISTER → check Amount Paid / Balance / Payment Status auto-update from PAYMENTS.
A7: 2) ATTENDANCE_DAILY → filter by a learner or date and confirm ATTENDANCE_SUMMARY updates automatically.
A8: 3) ASSESSMENTS → filter by learner and confirm PROGRESS_SUMMARY updates (overall and subject averages).
A9: 4) REPORT_TEMPLATE → change cell B3 to any student number in MASTER_REGISTER for a general report.
A10: 5) TERM_REPORT_TEMPLATE → set Start Date and End Date to a term range (e.g., 2026-01-01 to 2026-03-31) and change B3 to generate term-specific averages.
A12: Tip: If Excel doesn’t update immediately, press Ctrl + Alt + F9 once (full recalculation).

Sheet ADMIN_DASHBOARD
A1: Math & Sciences Hub – Admin Dashboard
A2: Overview
A4: Total Registered Learners | E4: Active Learners
A5: =COUNTIF(MASTER_REGISTER!E:E,"MSH*") -> 60 | E5: =COUNTIFS(MASTER_REGISTER!E:E,"MSH*",MASTER_REGISTER!K:K,"Active") -> 60
A7: Total Fees Billed (R) | E7: Total Paid (R)
A8: =SUM(MASTER_REGISTER!J:J) -> 164900 | E8: =SUM(MASTER_REGISTER!L:L) -> 103328.58
A10: Total Outstanding (R) | E10: Collection Rate
A11: =SUM(MASTER_REGISTER!M:M) -> 61571.42 | E11: =IFERROR(D5/C5,0) -> 0
A13: Avg Attendance % | E13: Avg Assessment Score %
A14: =IFERROR(AVERAGEIF(ATTENDANCE_SUMMARY!G:G,">0"),0) -> 0.871875 | E14: =IFERROR(AVERAGEIF(PROGRESS_SUMMARY!E:E,">0"),0) -> 63.616667
A18: Exports
A19: Use the EXPORTS sheet to copy/paste or save as CSV/XLSX for reporting.
A20: Tip: Filter the EXPORTS tables first, then Export/Save As.

Sheet EXPORTS
A1: Math & Sciences Hub – Exports
A3: EXPORT: Learners
A4: Student Number | B4: Full Name | C4: Grade | D4: Phone | E4: Email | F4: Package | G4: Total Fee | H4: Amount Paid | I4: Balance | J4: Payment Status
A5: =IF(MASTER_REGISTER!E2="","",MASTER_REGISTER!E2) -> MSH202608001 | B5: =IF($A5="","",MASTER_REGISTER!F2) -> Lerato Nkosi | C5: =IF($A5="","",MASTER_REGISTER!C2) -> 8 | D5: =IF($A5="","",MASTER_REGISTER!H2) -> 0782010000 | E5: =IF($A5="","",MASTER_REGISTER!G2) -> lerato.nkosi.demo8001@gmail.com | F5: =IF($A5="","",MASTER_REGISTER!I2) -> Senior Phase Support Package | G5: =IF($A5="","",MASTER_REGISTER!J2) -> 2400 | H5: =IF($A5="","",MASTER_REGISTER!L2) -> 920.52 | I5: =IF($A5="","",MASTER_REGISTER!M2) -> 1479.48 | J5: =IF($A5="","",MASTER_REGISTER!N2) -> Part Paid
A6: =IF(MASTER_REGISTER!E3="","",MASTER_REGISTER!E3) -> MSH202608002 | B6: =IF($A6="","",MASTER_REGISTER!F3) -> Karabo Maseko | C6: =IF($A6="","",MASTER_REGISTER!C3) -> 8 | D6: =IF($A6="","",MASTER_REGISTER!H3) -> 0782010001 | E6: =IF($A6="","",MASTER_REGISTER!G3) -> karabo.maseko.demo8002@gmail.com | F6: =IF($A6="","",MASTER_REGISTER!I3) -> Senior Phase Support Package | G6: =IF($A6="","",MASTER_REGISTER!J3) -> 2400 | H6: =IF($A6="","",MASTER_REGISTER!L3) -> 1458.28 | I6: =IF($A6="","",MASTER_REGISTER!M3) -> 941.72 | J6: =IF($A6="","",MASTER_REGISTER!N3) -> Part Paid
A7: =IF(MASTER_REGISTER!E4="","",MASTER_REGISTER!E4) -> MSH202608003 | B7: =IF($A7="","",MASTER_REGISTER!F4) -> Sifiso Sithole | C7: =IF($A7="","",MASTER_REGISTER!C4) -> 8 | D7: =IF($A7="","",MASTER_REGISTER!H4) -> 0782010002 | E7: =IF($A7="","",MASTER_REGISTER!G4) -> sifiso.sithole.demo8003@gmail.com | F7: =IF($A7="","",MASTER_REGISTER!I4) -> Senior Phase Support Package | G7: =IF($A7="","",MASTER_REGISTER!J4) -> 2400 | H7: =IF($A7="","",MASTER_REGISTER!L4) -> 893.15 | I7: =IF($A7="","",MASTER_REGISTER!M4) -> 1506.85 | J7: =IF($A7="","",MASTER_REGISTER!N4) -> Part Paid
A8: =IF(MASTER_REGISTER!E5="","",MASTER_REGISTER!E5) -> MSH202608004 | B8: =IF($A8="","",MASTER_REGISTER!F5) -> Tshepo Ndlovu | C8: =IF($A8="","",MASTER_REGISTER!C5) -> 8 | D8: =IF($A8="","",MASTER_REGISTER!H5) -> 0782010003 | E8: =IF($A8="","",MASTER_REGISTER!G5) -> tshepo.ndlovu.demo8004@gmail.com | F8: =IF($A8="","",MASTER_REGISTER!I5) -> Senior Phase Support Package | G8: =IF($A8="","",MASTER_REGISTER!J5) -> 2400 | H8: =IF($A8="","",MASTER_REGISTER!L5) -> 2012.41 | I8: =IF($A8="","",MASTER_REGISTER!M5) -> 387.59 | J8: =IF($A8="","",MASTER_REGISTER!N5) -> Part Paid
A9: =IF(MASTER_REGISTER!E6="","",MASTER_REGISTER!E6) -> MSH202608005 | B9: =IF($A9="","",MASTER_REGISTER!F6) -> Lwazi Mthembu | C9: =IF($A9="","",MASTER_REGISTER!C6) -> 8 | D9: =IF($A9="","",MASTER_REGISTER!H6) -> 0782010004 | E9: =IF($A9="","",MASTER_REGISTER!G6) -> lwazi.mthembu.demo8005@gmail.com | F9: =IF($A9="","",MASTER_REGISTER!I6) -> Senior Phase Support Package | G9: =IF($A9="","",MASTER_REGISTER!J6) -> 3400 | H9: =IF($A9="","",MASTER_REGISTER!L6) -> 2859.41 | I9: =IF($A9="","",MASTER_REGISTER!M6) -> 540.59 | J9: =IF($A9="","",MASTER_REGISTER!N6) -> Part Paid
A10: =IF(MASTER_REGISTER!E7="","",MASTER_REGISTER!E7) -> MSH202608006 | B10: =IF($A10="","",MASTER_REGISTER!F7) -> Karabo Ngobeni | C10: =IF($A10="","",MASTER_REGISTER!C7) -> 8 | D10: =IF($A10="","",MASTER_REGISTER!H7) -> 0782010005 | E10: =IF($A10="","",MASTER_REGISTER!G7) -> karabo.ngobeni.demo8006@gmail.com | F10: =IF($A10="","",MASTER_REGISTER!I7) -> Senior Phase Support Package | G10: =IF($A10="","",MASTER_REGISTER!J7) -> 2400 | H10: =IF($A10="","",MASTER_REGISTER!L7) -> 1588.63 | I10: =IF($A10="","",MASTER_REGISTER!M7) -> 811.37 | J10: =IF($A10="","",MASTER_REGISTER!N7) -> Part Paid
A11: =IF(MASTER_REGISTER!E8="","",MASTER_REGISTER!E8) -> MSH202608007 | B11: =IF($A11="","",MASTER_REGISTER!F8) -> Mpho Sithole | C11: =IF($A11="","",MASTER_REGISTER!C8) -> 8 | D11: =IF($A11="","",MASTER_REGISTER!H8) -> 0782010006 | E11: =IF($A11="","",MASTER_REGISTER!G8) -> mpho.sithole.demo8007@gmail.com | F11: =IF($A11="","",MASTER_REGISTER!I8) -> Senior Phase Support Package | G11: =IF($A11="","",MASTER_REGISTER!J8) -> 2400 | H11: =IF($A11="","",MASTER_REGISTER!L8) -> 1169.52 | I11: =IF($A11="","",MASTER_REGISTER!M8) -> 1230.48 | J11: =IF($A11="","",MASTER_REGISTER!N8) -> Part Paid
A12: =IF(MASTER_REGISTER!E9="","",MASTER_REGISTER!E9) -> MSH202608008 | B12: =IF($A12="","",MASTER_REGISTER!F9) -> Tshepo Ramushu | C12: =IF($A12="","",MASTER_REGISTER!C9) -> 8 | D12: =IF($A12="","",MASTER_REGISTER!H9) -> 0782010007 | E12: =IF($A12="","",MASTER_REGISTER!G9) -> tshepo.ramushu.demo8008@gmail.com | F12: =IF($A12="","",MASTER_REGISTER!I9) -> Senior Phase Support Package | G12: =IF($A12="","",MASTER_REGISTER!J9) -> 3400 | H12: =IF($A12="","",MASTER_REGISTER!L9) -> 1757.63 | I12: =IF($A12="","",MASTER_REGISTER!M9) -> 1642.37 | J12: =IF($A12="","",MASTER_REGISTER!N9) -> Part Paid
A13: =IF(MASTER_REGISTER!E10="","",MASTER_REGISTER!E10) -> MSH202608009 | B13: =IF($A13="","",MASTER_REGISTER!F10) -> Lerato Kekana | C13: =IF($A13="","",MASTER_REGISTER!C10) -> 8 | D13: =IF($A13="","",MASTER_REGISTER!H10) -> 0782010008 | E13: =IF($A13="","",MASTER_REGISTER!G10) -> lerato.kekana.demo8009@gmail.com | F13: =IF($A13="","",MASTER_REGISTER!I10) -> Senior Phase Support Package | G13: =IF($A13="","",MASTER_REGISTER!J10) -> 3400 | H13: =IF($A13="","",MASTER_REGISTER!L10) -> 2015.05 | I13: =IF($A13="","",MASTER_REGISTER!M10) -> 1384.95 | J13: =IF($A13="","",MASTER_REGISTER!N10) -> Part Paid
A14: =IF(MASTER_REGISTER!E11="","",MASTER_REGISTER!E11) -> MSH202608010 | B14: =IF($A14="","",MASTER_REGISTER!F11) -> Neo Ngobeni | C14: =IF($A14="","",MASTER_REGISTER!C11) -> 8 | D14: =IF($A14="","",MASTER_REGISTER!H11) -> 0782010009 | E14: =IF($A14="","",MASTER_REGISTER!G11) -> neo.ngobeni.demo8010@gmail.com | F14: =IF($A14="","",MASTER_REGISTER!I11) -> Senior Phase Support Package | G14: =IF($A14="","",MASTER_REGISTER!J11) -> 3400 | H14: =IF($A14="","",MASTER_REGISTER!L11) -> 2034.14 | I14: =IF($A14="","",MASTER_REGISTER!M11) -> 1365.86 | J14: =IF($A14="","",MASTER_REGISTER!N11) -> Part Paid
A15: =IF(MASTER_REGISTER!E12="","",MASTER_REGISTER!E12) -> MSH202608011 | B15: =IF($A15="","",MASTER_REGISTER!F12) -> Thabo Mokgadi | C15: =IF($A15="","",MASTER_REGISTER!C12) -> 8 | D15: =IF($A15="","",MASTER_REGISTER!H12) -> 0782010010 | E15: =IF($A15="","",MASTER_REGISTER!G12) -> thabo.mokgadi.demo8011@gmail.com | F15: =IF($A15="","",MASTER_REGISTER!I12) -> Senior Phase Support Package | G15: =IF($A15="","",MASTER_REGISTER!J12) -> 3400 | H15: =IF($A15="","",MASTER_REGISTER!L12) -> 1517.86 | I15: =IF($A15="","",MASTER_REGISTER!M12) -> 1882.14 | J15: =IF($A15="","",MASTER_REGISTER!N12) -> Part Paid
A16: =IF(MASTER_REGISTER!E13="","",MASTER_REGISTER!E13) -> MSH202608012 | B16: =IF($A16="","",MASTER_REGISTER!F13) -> Sifiso Mthembu | C16: =IF($A16="","",MASTER_REGISTER!C13) -> 8 | D16: =IF($A16="","",MASTER_REGISTER!H13) -> 0782010011 | E16: =IF($A16="","",MASTER_REGISTER!G13) -> sifiso.mthembu.demo8012@gmail.com | F16: =IF($A16="","",MASTER_REGISTER!I13) -> Senior Phase Support Package | G16: =IF($A16="","",MASTER_REGISTER!J13) -> 2400 | H16: =IF($A16="","",MASTER_REGISTER!L13) -> 2081.64 | I16: =IF($A16="","",MASTER_REGISTER!M13) -> 318.36 | J16: =IF($A16="","",MASTER_REGISTER!N13) -> Part Paid
... A504: =IF(MASTER_REGISTER!E501="","",MASTER_REGISTER!E501) | B504: =IF($A504="","",MASTER_REGISTER!F501) | C504: =IF($A504="","",MASTER_REGISTER!C501) | D504: =IF($A504="","",MASTER_REGISTER!H501) | E504: =IF($A504="","",MASTER_REGISTER!G501) | F504: =IF($A504="","",MASTER_REGISTER!I501) | G504: =IF($A504="","",MASTER_REGISTER!J501) | H504: =IF($A504="","",MASTER_REGISTER!L501) | I504: =IF($A504="","",MASTER_REGISTER!M501) | J504: =IF($A504="","",MASTER_REGISTER!N501)
A506: EXPORT: Payments
A507: Payment Date | B507: Receipt/Ref | C507: Student Number | D507: Payer Name | E507: Amount Paid (R) | F507: Method | G507: Notes
A508: =IF(PAYMENTS!A1="","",PAYMENTS!A1) -> Payment Date | B508: =IF($A508="","",PAYMENTS!B1) -> Receipt/Ref | C508: =IF($A508="","",PAYMENTS!C1) -> Student Number | D508: =IF($A508="","",PAYMENTS!D1) -> Payer Name | E508: =IF($A508="","",PAYMENTS!E1) -> Amount Paid (R) | F508: =IF($A508="","",PAYMENTS!F1) -> Method | G508: =IF($A508="","",PAYMENTS!G1) -> Notes
A509: =IF(PAYMENTS!A2="","",PAYMENTS!A2) -> 2026-02-10 | B509: =IF($A509="","",PAYMENTS!B2) -> MSH-R1001 | C509: =IF($A509="","",PAYMENTS!C2) -> MSH202608001 | D509: =IF($A509="","",PAYMENTS!D2) -> Lerato Nkosi | E509: =IF($A509="","",PAYMENTS!E2) -> 316.93 | F509: =IF($A509="","",PAYMENTS!F2) -> Cash | G509: =IF($A509="","",PAYMENTS!G2) -> Term payment 2
A510: =IF(PAYMENTS!A3="","",PAYMENTS!A3) -> 2026-03-05 | B510: =IF($A510="","",PAYMENTS!B3) -> MSH-R1002 | C510: =IF($A510="","",PAYMENTS!C3) -> MSH202608001 | D510: =IF($A510="","",PAYMENTS!D3) -> Lerato Nkosi | E510: =IF($A510="","",PAYMENTS!E3) -> 185.38 | F510: =IF($A510="","",PAYMENTS!F3) -> Card | G510: =IF($A510="","",PAYMENTS!G3) -> Term payment 3
A511: =IF(PAYMENTS!A4="","",PAYMENTS!A4) -> 2026-07-15 | B511: =IF($A511="","",PAYMENTS!B4) -> MSH-R1003 | C511: =IF($A511="","",PAYMENTS!C4) -> MSH202608001 | D511: =IF($A511="","",PAYMENTS!D4) -> Lerato Nkosi | E511: =IF($A511="","",PAYMENTS!E4) -> 174.28 | F511: =IF($A511="","",PAYMENTS!F4) -> Cash | G511: =IF($A511="","",PAYMENTS!G4) -> Term payment 7
A512: =IF(PAYMENTS!A5="","",PAYMENTS!A5) -> 2026-08-10 | B512: =IF($A512="","",PAYMENTS!B5) -> MSH-R1004 | C512: =IF($A512="","",PAYMENTS!C5) -> MSH202608001 | D512: =IF($A512="","",PAYMENTS!D5) -> Lerato Nkosi | E512: =IF($A512="","",PAYMENTS!E5) -> 243.93 | F512: =IF($A512="","",PAYMENTS!F5) -> Cash | G512: =IF($A512="","",PAYMENTS!G5) -> Term payment 8
A513: =IF(PAYMENTS!A6="","",PAYMENTS!A6) -> 2026-02-05 | B513: =IF($A513="","",PAYMENTS!B6) -> MSH-R1005 | C513: =IF($A513="","",PAYMENTS!C6) -> MSH202608002 | D513: =IF($A513="","",PAYMENTS!D6) -> Karabo Maseko | E513: =IF($A513="","",PAYMENTS!E6) -> 179.92 | F513: =IF($A513="","",PAYMENTS!F6) -> EFT | G513: =IF($A513="","",PAYMENTS!G6) -> Term payment 2
A514: =IF(PAYMENTS!A7="","",PAYMENTS!A7) -> 2026-03-15 | B514: =IF($A514="","",PAYMENTS!B7) -> MSH-R1006 | C514: =IF($A514="","",PAYMENTS!C7) -> MSH202608002 | D514: =IF($A514="","",PAYMENTS!D7) -> Karabo Maseko | E514: =IF($A514="","",PAYMENTS!E7) -> 190.17 | F514: =IF($A514="","",PAYMENTS!F7) -> EFT | G514: =IF($A514="","",PAYMENTS!G7) -> Term payment 3
A515: =IF(PAYMENTS!A8="","",PAYMENTS!A8) -> 2026-06-01 | B515: =IF($A515="","",PAYMENTS!B8) -> MSH-R1007 | C515: =IF($A515="","",PAYMENTS!C8) -> MSH202608002 | D515: =IF($A515="","",PAYMENTS!D8) -> Karabo Maseko | E515: =IF($A515="","",PAYMENTS!E8) -> 179.56 | F515: =IF($A515="","",PAYMENTS!F8) -> Cash | G515: =IF($A515="","",PAYMENTS!G8) -> Term payment 6
A516: =IF(PAYMENTS!A9="","",PAYMENTS!A9) -> 2026-07-15 | B516: =IF($A516="","",PAYMENTS!B9) -> MSH-R1008 | C516: =IF($A516="","",PAYMENTS!C9) -> MSH202608002 | D516: =IF($A516="","",PAYMENTS!D9) -> Karabo Maseko | E516: =IF($A516="","",PAYMENTS!E9) -> 201.28 | F516: =IF($A516="","",PAYMENTS!F9) -> EFT | G516: =IF($A516="","",PAYMENTS!G9) -> Term payment 7
A517: =IF(PAYMENTS!A10="","",PAYMENTS!A10) -> 2026-08-10 | B517: =IF($A517="","",PAYMENTS!B10) -> MSH-R1009 | C517: =IF($A517="","",PAYMENTS!C10) -> MSH202608002 | D517: =IF($A517="","",PAYMENTS!D10) -> Karabo Maseko | E517: =IF($A517="","",PAYMENTS!E10) -> 235.37 | F517: =IF($A517="","",PAYMENTS!F10) -> Card | G517: =IF($A517="","",PAYMENTS!G10) -> Term payment 8
A518: =IF(PAYMENTS!A11="","",PAYMENTS!A11) -> 2026-09-20 | B518: =IF($A518="","",PAYMENTS!B11) -> MSH-R1010 | C518: =IF($A518="","",PAYMENTS!C11) -> MSH202608002 | D518: =IF($A518="","",PAYMENTS!D11) -> Karabo Maseko | E518: =IF($A518="","",PAYMENTS!E11) -> 286.96 | F518: =IF($A518="","",PAYMENTS!F11) -> EFT | G518: =IF($A518="","",PAYMENTS!G11) -> Term payment 9
A519: =IF(PAYMENTS!A12="","",PAYMENTS!A12) -> 2026-10-05 | B519: =IF($A519="","",PAYMENTS!B12) -> MSH-R1011 | C519: =IF($A519="","",PAYMENTS!C12) -> MSH202608002 | D519: =IF($A519="","",PAYMENTS!D12) -> Karabo Maseko | E519: =IF($A519="","",PAYMENTS!E12) -> 185.02 | F519: =IF($A519="","",PAYMENTS!F12) -> Cash | G519: =IF($A519="","",PAYMENTS!G12) -> Term payment 10
... A1007: =IF(PAYMENTS!A500="","",PAYMENTS!A500) | B1007: =IF($A1007="","",PAYMENTS!B500) | C1007: =IF($A1007="","",PAYMENTS!C500) | D1007: =IF($A1007="","",PAYMENTS!D500) | E1007: =IF($A1007="","",PAYMENTS!E500) | F1007: =IF($A1007="","",PAYMENTS!F500) | G1007: =IF($A1007="","",PAYMENTS!G500)

Sheet MASTER_REGISTER
A1: Registration Date | B1: Year | C1: Grade | D1: Applicant Sequence | E1: Student Number | F1: Full Name | G1: Email | H1: Phone | I1: Package Name | J1: Total Fee | K1: Status | L1: Amount Paid (R) | M1: Balance (R) | N1: Payment Status | O1: Last Payment Date
A2: 2026-01-06 | B2: 2026 | C2: 8 | D2: 001 | E2: MSH202608001 | F2: Lerato Nkosi | G2: lerato.nkosi.demo8001@gmail.com | H2: 0782010000 | I2: Senior Phase Support Package | J2: 2400 | K2: Active | L2: =IF(E2="","",SUMIF(PAYMENTS!C:C,E2,PAYMENTS!E:E)) -> 920.52 | M2: =IF(E2="","",J2-L2) -> 1479.48 | N2: =IF(E2="","",IF(M2<=0,"Paid",IF(L2>0,"Part Paid","Unpaid"))) -> Part Paid | O2: =IF(E2="","",IFERROR(_xludf.MAXIFS(PAYMENTS!A:A,PAYMENTS!C:C,E2),""))
A3: 2026-01-08 | B3: 2026 | C3: 8 | D3: 002 | E3: MSH202608002 | F3: Karabo Maseko | G3: karabo.maseko.demo8002@gmail.com | H3: 0782010001 | I3: Senior Phase Support Package | J3: 2400 | K3: Active | L3: =IF(E3="","",SUMIF(PAYMENTS!C:C,E3,PAYMENTS!E:E)) -> 1458.28 | M3: =IF(E3="","",J3-L3) -> 941.72 | N3: =IF(E3="","",IF(M3<=0,"Paid",IF(L3>0,"Part Paid","Unpaid"))) -> Part Paid | O3: =IF(E3="","",IFERROR(_xludf.MAXIFS(PAYMENTS!A:A,PAYMENTS!C:C,E3),""))
A4: 2026-01-10 | B4: 2026 | C4: 8 | D4: 003 | E4: MSH202608003 | F4: Sifiso Sithole | G4: sifiso.sithole.demo8003@gmail.com | H4: 0782010002 | I4: Senior Phase Support Package | J4: 2400 | K4: Active | L4: =IF(E4="","",SUMIF(PAYMENTS!C:C,E4,PAYMENTS!E:E)) -> 893.15 | M4: =IF(E4="","",J4-L4) -> 1506.85 | N4: =IF(E4="","",IF(M4<=0,"Paid",IF(L4>0,"Part Paid","Unpaid"))) -> Part Paid | O4: =IF(E4="","",IFERROR(_xludf.MAXIFS(PAYMENTS!A:A,PAYMENTS!C:C,E4),""))
A5: 2026-01-12 | B5: 2026 | C5: 8 | D5: 004 | E5: MSH202608004 | F5: Tshepo Ndlovu | G5: tshepo.ndlovu.demo8004@gmail.com | H5: 0782010003 | I5: Senior Phase Support Package | J5: 2400 | K5: Active | L5: =IF(E5="","",SUMIF(PAYMENTS!C:C,E5,PAYMENTS!E:E)) -> 2012.41 | M5: =IF(E5="","",J5-L5) -> 387.59 | N5: =IF(E5="","",IF(M5<=0,"Paid",IF(L5>0,"Part Paid","Unpaid"))) -> Part Paid | O5: =IF(E5="","",IFERROR(_xludf.MAXIFS(PAYMENTS!A:A,PAYMENTS!C:C,E5),""))
A6: 2026-01-14 | B6: 2026 | C6: 8 | D6: 005 | E6: MSH202608005 | F6: Lwazi Mthembu | G6: lwazi.mthembu.demo8005@gmail.com | H6: 0782010004 | I6: Senior Phase Support Package | J6: 3400 | K6: Active | L6: =IF(E6="","",SUMIF(PAYMENTS!C:C,E6,PAYMENTS!E:E)) -> 2859.41 | M6: =IF(E6="","",J6-L6) -> 540.59 | N6: =IF(E6="","",IF(M6<=0,"Paid",IF(L6>0,"Part Paid","Unpaid"))) -> Part Paid | O6: =IF(E6="","",IFERROR(_xludf.MAXIFS(PAYMENTS!A:A,PAYMENTS!C:C,E6),""))
A7: 2026-01-16 | B7: 2026 | C7: 8 | D7: 006 | E7: MSH202608006 | F7: Karabo Ngobeni | G7: karabo.ngobeni.demo8006@gmail.com | H7: 0782010005 | I7: Senior Phase Support Package | J7: 2400 | K7: Active | L7: =IF(E7="","",SUMIF(PAYMENTS!C:C,E7,PAYMENTS!E:E)) -> 1588.63 | M7: =IF(E7="","",J7-L7) -> 811.37 | N7: =IF(E7="","",IF(M7<=0,"Paid",IF(L7>0,"Part Paid","Unpaid"))) -> Part Paid | O7: =IF(E7="","",IFERROR(_xludf.MAXIFS(PAYMENTS!A:A,PAYMENTS!C:C,E7),""))
A8: 2026-01-18 | B8: 2026 | C8: 8 | D8: 007 | E8: MSH202608007 | F8: Mpho Sithole | G8: mpho.sithole.demo8007@gmail.com | H8: 0782010006 | I8: Senior Phase Support Package | J8: 2400 | K8: Active | L8: =IF(E8="","",SUMIF(PAYMENTS!C:C,E8,PAYMENTS!E:E)) -> 1169.52 | M8: =IF(E8="","",J8-L8) -> 1230.48 | N8: =IF(E8="","",IF(M8<=0,"Paid",IF(L8>0,"Part Paid","Unpaid"))) -> Part Paid | O8: =IF(E8="","",IFERROR(_xludf.MAXIFS(PAYMENTS!A:A,PAYMENTS!C:C,E8),""))
A9: 2026-01-20 | B9: 2026 | C9: 8 | D9: 008 | E9: MSH202608008 | F9: Tshepo Ramushu | G9: tshepo.ramushu.demo8008@gmail.com | H9: 0782010007 | I9: Senior Phase Support Package | J9: 3400 | K9: Active | L9: =IF(E9="","",SUMIF(PAYMENTS!C:C,E9,PAYMENTS!E:E)) -> 1757.63 | M9: =IF(E9="","",J9-L9) -> 1642.37 | N9: =IF(E9="","",IF(M9<=0,"Paid",IF(L9>0,"Part Paid","Unpaid"))) -> Part Paid | O9: =IF(E9="","",IFERROR(_xludf.MAXIFS(PAYMENTS!A:A,PAYMENTS!C:C,E9),""))
A10: 2026-01-22 | B10: 2026 | C10: 8 | D10: 009 | E10: MSH202608009 | F10: Lerato Kekana | G10: lerato.kekana.demo8009@gmail.com | H10: 0782010008 | I10: Senior Phase Support Package | J10: 3400 | K10: Active | L10: =IF(E10="","",SUMIF(PAYMENTS!C:C,E10,PAYMENTS!E:E)) -> 2015.05 | M10: =IF(E10="","",J10-L10) -> 1384.95 | N10: =IF(E10="","",IF(M10<=0,"Paid",IF(L10>0,"Part Paid","Unpaid"))) -> Part Paid | O10: =IF(E10="","",IFERROR(_xludf.MAXIFS(PAYMENTS!A:A,PAYMENTS!C:C,E10),""))
A11: 2026-01-24 | B11: 2026 | C11: 8 | D11: 010 | E11: MSH202608010 | F11: Neo Ngobeni | G11: neo.ngobeni.demo8010@gmail.com | H11: 0782010009 | I11: Senior Phase Support Package | J11: 3400 | K11: Active | L11: =IF(E11="","",SUMIF(PAYMENTS!C:C,E11,PAYMENTS!E:E)) -> 2034.14 | M11: =IF(E11="","",J11-L11) -> 1365.86 | N11: =IF(E11="","",IF(M11<=0,"Paid",IF(L11>0,"Part Paid","Unpaid"))) -> Part Paid | O11: =IF(E11="","",IFERROR(_xludf.MAXIFS(PAYMENTS!A:A,PAYMENTS!C:C,E11),""))
A12: 2026-01-26 | B12: 2026 | C12: 8 | D12: 011 | E12: MSH202608011 | F12: Thabo Mokgadi | G12: thabo.mokgadi.demo8011@gmail.com | H12: 0782010010 | I12: Senior Phase Support Package | J12: 3400 | K12: Active | L12: =IF(E12="","",SUMIF(PAYMENTS!C:C,E12,PAYMENTS!E:E)) -> 1517.86 | M12: =IF(E12="","",J12-L12) -> 1882.14 | N12: =IF(E12="","",IF(M12<=0,"Paid",IF(L12>0,"Part Paid","Unpaid"))) -> Part Paid | O12: =IF(E12="","",IFERROR(_xludf.MAXIFS(PAYMENTS!A:A,PAYMENTS!C:C,E12),""))
A13: 2026-01-28 | B13: 2026 | C13: 8 | D13: 012 | E13: MSH202608012 | F13: Sifiso Mthembu | G13: sifiso.mthembu.demo8012@gmail.com | H13: 0782010011 | I13: Senior Phase Support Package | J13: 2400 | K13: Active | L13: =IF(E13="","",SUMIF(PAYMENTS!C:C,E13,PAYMENTS!E:E)) -> 2081.64 | M13: =IF(E13="","",J13-L13) -> 318.36 | N13: =IF(E13="","",IF(M13<=0,"Paid",IF(L13>0,"Part Paid","Unpaid"))) -> Part Paid | O13: =IF(E13="","",IFERROR(_xludf.MAXIFS(PAYMENTS!A:A,PAYMENTS!C:C,E13),""))
... A61: 2026-01-24 | B61: 2026 | C61: 12 | D61: 012 | E61: MSH202612012 | F61: Sibusiso Ngobeni | G61: sibusiso.ngobeni.demo12012@gmail.com | H61: 0782010059 | I61: General Support Package | J61: 1900 | K61: Active | L61: =IF(E61="","",SUMIF(PAYMENTS!C:C,E61,PAYMENTS!E:E)) -> 1419.34 | M61: =IF(E61="","",J61-L61) -> 480.66 | N61: =IF(E61="","",IF(M61<=0,"Paid",IF(L61>0,"Part Paid","Unpaid"))) -> Part Paid | O61: =IF(E61="","",IFERROR(_xludf.MAXIFS(PAYMENTS!A:A,PAYMENTS!C:C,E61),""))
L62: =IF(E62="","",SUMIF(PAYMENTS!C:C,E62,PAYMENTS!E:E)) | M62: =IF(E62="","",J62-L62) | N62: =IF(E62="","",IF(M62<=0,"Paid",IF(L62>0,"Part Paid","Unpaid"))) | O62: =IF(E62="","",IFERROR(_xludf.MAXIFS(PAYMENTS!A:A,PAYMENTS!C:C,E62),""))
L63: =IF(E63="","",SUMIF(PAYMENTS!C:C,E63,PAYMENTS!E:E)) | M63: =IF(E63="","",J63-L63) | N63: =IF(E63="","",IF(M63<=0,"Paid",IF(L63>0,"Part Paid","Unpaid"))) | O63: =IF(E63="","",IFERROR(_xludf.MAXIFS(PAYMENTS!A:A,PAYMENTS!C:C,E63),""))
L64: =IF(E64="","",SUMIF(PAYMENTS!C:C,E64,PAYMENTS!E:E)) | M64: =IF(E64="","",J64-L64) | N64: =IF(E64="","",IF(M64<=0,"Paid",IF(L64>0,"Part Paid","Unpaid"))) | O64: =IF(E64="","",IFERROR(_xludf.MAXIFS(PAYMENTS!A:A,PAYMENTS!C:C,E64),""))
L65: =IF(E65="","",SUMIF(PAYMENTS!C:C,E65,PAYMENTS!E:E)) | M65: =IF(E65="","",J65-L65) | N65: =IF(E65="","",IF(M65<=0,"Paid",IF(L65>0,"Part Paid","Unpaid"))) | O65: =IF(E65="","",IFERROR(_xludf.MAXIFS(PAYMENTS!A:A,PAYMENTS!C:C,E65),""))
L66: =IF(E66="","",SUMIF(PAYMENTS!C:C,E66,PAYMENTS!E:E)) | M66: =IF(E66="","",J66-L66) | N66: =IF(E66="","",IF(M66<=0,"Paid",IF(L66>0,"Part Paid","Unpaid"))) | O66: =IF(E66="","",IFERROR(_xludf.MAXIFS(PAYMENTS!A:A,PAYMENTS!C:C,E66),""))
L67: =IF(E67="","",SUMIF(PAYMENTS!C:C,E67,PAYMENTS!E:E)) | M67: =IF(E67="","",J67-L67) | N67: =IF(E67="","",IF(M67<=0,"Paid",IF(L67>0,"Part Paid","Unpaid"))) | O67: =IF(E67="","",IFERROR(_xludf.MAXIFS(PAYMENTS!A:A,PAYMENTS!C:C,E67),""))
L68: =IF(E68="","",SUMIF(PAYMENTS!C:C,E68,PAYMENTS!E:E)) | M68: =IF(E68="","",J68-L68) | N68: =IF(E68="","",IF(M68<=0,"Paid",IF(L68>0,"Part Paid","Unpaid"))) | O68: =IF(E68="","",IFERROR(_xludf.MAXIFS(PAYMENTS!A:A,PAYMENTS!C:C,E68),""))
L69: =IF(E69="","",SUMIF(PAYMENTS!C:C,E69,PAYMENTS!E:E)) | M69: =IF(E69="","",J69-L69) | N69: =IF(E69="","",IF(M69<=0,"Paid",IF(L69>0,"Part Paid","Unpaid"))) | O69: =IF(E69="","",IFERROR(_xludf.MAXIFS(PAYMENTS!A:A,PAYMENTS!C:C,E69),""))
L70: =IF(E70="","",SUMIF(PAYMENTS!C:C,E70,PAYMENTS!E:E)) | M70: =IF(E70="","",J70-L70) | N70: =IF(E70="","",IF(M70<=0,"Paid",IF(L70>0,"Part Paid","Unpaid"))) | O70: =IF(E70="","",IFERROR(_xludf.MAXIFS(PAYMENTS!A:A,PAYMENTS!C:C,E70),""))
L71: =IF(E71="","",SUMIF(PAYMENTS!C:C,E71,PAYMENTS!E:E)) | M71: =IF(E71="","",J71-L71) | N71: =IF(E71="","",IF(M71<=0,"Paid",IF(L71>0,"Part Paid","Unpaid"))) | O71: =IF(E71="","",IFERROR(_xludf.MAXIFS(PAYMENTS!A:A,PAYMENTS!C:C,E71),""))
L72: =IF(E72="","",SUMIF(PAYMENTS!C:C,E72,PAYMENTS!E:E)) | M72: =IF(E72="","",J72-L72) | N72: =IF(E72="","",IF(M72<=0,"Paid",IF(L72>0,"Part Paid","Unpaid"))) | O72: =IF(E72="","",IFERROR(_xludf.MAXIFS(PAYMENTS!A:A,PAYMENTS!C:C,E72),""))
L73: =IF(E73="","",SUMIF(PAYMENTS!C:C,E73,PAYMENTS!E:E)) | M73: =IF(E73="","",J73-L73) | N73: =IF(E73="","",IF(M73<=0,"Paid",IF(L73>0,"Part Paid","Unpaid"))) | O73: =IF(E73="","",IFERROR(_xludf.MAXIFS(PAYMENTS!A:A,PAYMENTS!C:C,E73),""))
... L1000: =IF(E1000="","",SUMIF(PAYMENTS!C:C,E1000,PAYMENTS!E:E)) | M1000: =IF(E1000="","",J1000-L1000) | N1000: =IF(E1000="","",IF(M1000<=0,"Paid",IF(L1000>0,"Part Paid","Unpaid"))) | O1000: =IF(E1000="","",IFERROR(_xludf.MAXIFS(PAYMENTS!A:A,PAYMENTS!C:C,E1000),""))

Sheet AUTO_IMPORT
A1: Registration Date | B1: Year | C1: Grade | D1: Applicant Sequence | E1: Student Number | F1: Full Name | G1: Email | H1: Phone | I1: Package Name | J1: Total Fee
A2: 2026-01-06 | B2: 2026 | C2: 8 | D2: 001 | E2: MSH202608001 | F2: Lerato Nkosi | G2: lerato.nkosi.demo8001@gmail.com | H2: 0782010000 | I2: Senior Phase Support Package | J2: 2400
A3: 2026-01-08 | B3: 2026 | C3: 8 | D3: 002 | E3: MSH202608002 | F3: Karabo Maseko | G3: karabo.maseko.demo8002@gmail.com | H3: 0782010001 | I3: Senior Phase Support Package | J3: 2400
A4: 2026-01-10 | B4: 2026 | C4: 8 | D4: 003 | E4: MSH202608003 | F4: Sifiso Sithole | G4: sifiso.sithole.demo8003@gmail.com | H4: 0782010002 | I4: Senior Phase Support Package | J4: 2400
A5: 2026-01-12 | B5: 2026 | C5: 8 | D5: 004 | E5: MSH202608004 | F5: Tshepo Ndlovu | G5: tshepo.ndlovu.demo8004@gmail.com | H5: 0782010003 | I5: Senior Phase Support Package | J5: 2400
A6: 2026-01-14 | B6: 2026 | C6: 8 | D6: 005 | E6: MSH202608005 | F6: Lwazi Mthembu | G6: lwazi.mthembu.demo8005@gmail.com | H6: 0782010004 | I6: Senior Phase Support Package | J6: 3400
A7: 2026-01-16 | B7: 2026 | C7: 8 | D7: 006 | E7: MSH202608006 | F7: Karabo Ngobeni | G7: karabo.ngobeni.demo8006@gmail.com | H7: 0782010005 | I7: Senior Phase Support Package | J7: 2400
A8: 2026-01-18 | B8: 2026 | C8: 8 | D8: 007 | E8: MSH202608007 | F8: Mpho Sithole | G8: mpho.sithole.demo8007@gmail.com | H8: 0782010006 | I8: Senior Phase Support Package | J8: 2400
A9: 2026-01-20 | B9: 2026 | C9: 8 | D9: 008 | E9: MSH202608008 | F9: Tshepo Ramushu | G9: tshepo.ramushu.demo8008@gmail.com | H9: 0782010007 | I9: Senior Phase Support Package | J9: 3400
A10: 2026-01-22 | B10: 2026 | C10: 8 | D10: 009 | E10: MSH202608009 | F10: Lerato Kekana | G10: lerato.kekana.demo8009@gmail.com | H10: 0782010008 | I10: Senior Phase Support Package | J10: 3400
A11: 2026-01-24 | B11: 2026 | C11: 8 | D11: 010 | E11: MSH202608010 | F11: Neo Ngobeni | G11: neo.ngobeni.demo8010@gmail.com | H11: 0782010009 | I11: Senior Phase Support Package | J11: 3400
A12: 2026-01-26 | B12: 2026 | C12: 8 | D12: 011 | E12: MSH202608011 | F12: Thabo Mokgadi | G12: thabo.mokgadi.demo8011@gmail.com | H12: 0782010010 | I12: Senior Phase Support Package | J12: 3400
A13: 2026-01-28 | B13: 2026 | C13: 8 | D13: 012 | E13: MSH202608012 | F13: Sifiso Mthembu | G13: sifiso.mthembu.demo8012@gmail.com | H13: 0782010011 | I13: Senior Phase Support Package | J13: 2400
... A26: 2026-02-23 | B26: 2026 | C26: 10 | D26: 001 | E26: MSH202610001 | F26: Lerato Maseko | G26: lerato.maseko.demo10001@gmail.com | H26: 0782010024 | I26: Commerce Package | J26: 3200

Sheet ATTENDANCE_DAILY
A1: Session Date | B1: Grade (auto) | C1: Student Number | D1: Learner Name (auto) | E1: Present? | F1: Arrival Time | G1: Departure Time | H1: Reason (if absent) | I1: Notes
A2: 2026-01-03 | B2: =IFERROR(INDEX(MASTER_REGISTER!C:C,MATCH(C2,MASTER_REGISTER!E:E,0)),"") -> 8 | C2: MSH202608001 | D2: =IFERROR(INDEX(MASTER_REGISTER!F:F,MATCH(C2,MASTER_REGISTER!E:E,0)),"") -> Lerato Nkosi | E2: Absent | H2: Other
A3: 2026-01-03 | B3: =IFERROR(INDEX(MASTER_REGISTER!C:C,MATCH(C3,MASTER_REGISTER!E:E,0)),"") -> 8 | C3: MSH202608002 | D3: =IFERROR(INDEX(MASTER_REGISTER!F:F,MATCH(C3,MASTER_REGISTER!E:E,0)),"") -> Karabo Maseko | E3: Present | F3: 07:05 | G3: 15:00
A4: 2026-01-03 | B4: =IFERROR(INDEX(MASTER_REGISTER!C:C,MATCH(C4,MASTER_REGISTER!E:E,0)),"") -> 8 | C4: MSH202608003 | D4: =IFERROR(INDEX(MASTER_REGISTER!F:F,MATCH(C4,MASTER_REGISTER!E:E,0)),"") -> Sifiso Sithole | E4: Present | F4: 07:05 | G4: 15:00
A5: 2026-01-03 | B5: =IFERROR(INDEX(MASTER_REGISTER!C:C,MATCH(C5,MASTER_REGISTER!E:E,0)),"") -> 8 | C5: MSH202608004 | D5: =IFERROR(INDEX(MASTER_REGISTER!F:F,MATCH(C5,MASTER_REGISTER!E:E,0)),"") -> Tshepo Ndlovu | E5: Present | F5: 07:05 | G5: 15:00
A6: 2026-01-03 | B6: =IFERROR(INDEX(MASTER_REGISTER!C:C,MATCH(C6,MASTER_REGISTER!E:E,0)),"") -> 8 | C6: MSH202608005 | D6: =IFERROR(INDEX(MASTER_REGISTER!F:F,MATCH(C6,MASTER_REGISTER!E:E,0)),"") -> Lwazi Mthembu | E6: Absent | H6: Transport issue
A7: 2026-01-03 | B7: =IFERROR(INDEX(MASTER_REGISTER!C:C,MATCH(C7,MASTER_REGISTER!E:E,0)),"") -> 8 | C7: MSH202608006 | D7: =IFERROR(INDEX(MASTER_REGISTER!F:F,MATCH(C7,MASTER_REGISTER!E:E,0)),"") -> Karabo Ngobeni | E7: Present | F7: 07:05 | G7: 15:00
A8: 2026-01-03 | B8: =IFERROR(INDEX(MASTER_REGISTER!C:C,MATCH(C8,MASTER_REGISTER!E:E,0)),"") -> 8 | C8: MSH202608007 | D8: =IFERROR(INDEX(MASTER_REGISTER!F:F,MATCH(C8,MASTER_REGISTER!E:E,0)),"") -> Mpho Sithole | E8: Present | F8: 07:05 | G8: 15:00
A9: 2026-01-03 | B9: =IFERROR(INDEX(MASTER_REGISTER!C:C,MATCH(C9,MASTER_REGISTER!E:E,0)),"") -> 8 | C9: MSH202608008 | D9: =IFERROR(INDEX(MASTER_REGISTER!F:F,MATCH(C9,MASTER_REGISTER!E:E,0)),"") -> Tshepo Ramushu | E9: Present | F9: 07:05 | G9: 15:00
A10: 2026-01-03 | B10: =IFERROR(INDEX(MASTER_REGISTER!C:C,MATCH(C10,MASTER_REGISTER!E:E,0)),"") -> 8 | C10: MSH202608009 | D10: =IFERROR(INDEX(MASTER_REGISTER!F:F,MATCH(C10,MASTER_REGISTER!E:E,0)),"") -> Lerato Kekana | E10: Present | F10: 07:05 | G10: 15:00
A11: 2026-01-03 | B11: =IFERROR(INDEX(MASTER_REGISTER!C:C,MATCH(C11,MASTER_REGISTER!E:E,0)),"") -> 8 | C11: MSH202608010 | D11: =IFERROR(INDEX(MASTER_REGISTER!F:F,MATCH(C11,MASTER_REGISTER!E:E,0)),"") -> Neo Ngobeni | E11: Present | F11: 07:05 | G11: 15:00
A12: 2026-01-03 | B12: =IFERROR(INDEX(MASTER_REGISTER!C:C,MATCH(C12,MASTER_REGISTER!E:E,0)),"") -> 8 | C12: MSH202608011 | D12: =IFERROR(INDEX(MASTER_REGISTER!F:F,MATCH(C12,MASTER_REGISTER!E:E,0)),"") -> Thabo Mokgadi | E12: Present | F12: 07:05 | G12: 15:00
A13: 2026-01-03 | B13: =IFERROR(INDEX(MASTER_REGISTER!C:C,MATCH(C13,MASTER_REGISTER!E:E,0)),"") -> 8 | C13: MSH202608012 | D13: =IFERROR(INDEX(MASTER_REGISTER!F:F,MATCH(C13,MASTER_REGISTER!E:E,0)),"") -> Sifiso Mthembu | E13: Present | F13: 07:05 | G13: 15:00
A14: 2026-01-03 | B14: =IFERROR(INDEX(MASTER_REGISTER!C:C,MATCH(C14,MASTER_REGISTER!E:E,0)),"") -> 9 | C14: MSH202609001 | D14: =IFERROR(INDEX(MASTER_REGISTER!F:F,MATCH(C14,MASTER_REGISTER!E:E,0)),"") -> Karabo Phiri | E14: Absent | H14: Other
A15: 2026-01-03 | B15: =IFERROR(INDEX(MASTER_REGISTER!C:C,MATCH(C15,MASTER_REGISTER!E:E,0)),"") -> 9 | C15: MSH202609002 | D15: =IFERROR(INDEX(MASTER_REGISTER!F:F,MATCH(C15,MASTER_REGISTER!E:E,0)),"") -> Lerato Mahlangu | E15: Present | F15: 07:05 | G15: 15:00
A16: 2026-01-03 | B16: =IFERROR(INDEX(MASTER_REGISTER!C:C,MATCH(C16,MASTER_REGISTER!E:E,0)),"") -> 9 | C16: MSH202609003 | D16: =IFERROR(INDEX(MASTER_REGISTER!F:F,MATCH(C16,MASTER_REGISTER!E:E,0)),"") -> Mpho Kekana | E16: Present | F16: 07:05 | G16: 15:00
A17: 2026-01-03 | B17: =IFERROR(INDEX(MASTER_REGISTER!C:C,MATCH(C17,MASTER_REGISTER!E:E,0)),"") -> 9 | C17: MSH202609004 | D17: =IFERROR(INDEX(MASTER_REGISTER!F:F,MATCH(C17,MASTER_REGISTER!E:E,0)),"") -> Thabo Molefe | E17: Present | F17: 07:05 | G17: 15:00
A18: 2026-01-03 | B18: =IFERROR(INDEX(MASTER_REGISTER!C:C,MATCH(C18,MASTER_REGISTER!E:E,0)),"") -> 9 | C18: MSH202609005 | D18: =IFERROR(INDEX(MASTER_REGISTER!F:F,MATCH(C18,MASTER_REGISTER!E:E,0)),"") -> Mpho Ngobeni | E18: Present | F18: 07:05 | G18: 15:00
A19: 2026-01-03 | B19: =IFERROR(INDEX(MASTER_REGISTER!C:C,MATCH(C19,MASTER_REGISTER!E:E,0)),"") -> 9 | C19: MSH202609006 | D19: =IFERROR(INDEX(MASTER_REGISTER!F:F,MATCH(C19,MASTER_REGISTER!E:E,0)),"") -> Siyanda Mhlongo | E19: Present | F19: 07:05 | G19: 15:00
A20: 2026-01-03 | B20: =IFERROR(INDEX(MASTER_REGISTER!C:C,MATCH(C20,MASTER_REGISTER!E:E,0)),"") -> 9 | C20: MSH202609007 | D20: =IFERROR(INDEX(MASTER_REGISTER!F:F,MATCH(C20,MASTER_REGISTER!E:E,0)),"") -> Siyanda Mahlangu | E20: Present | F20: 07:05 | G20: 15:00
A21: 2026-01-03 | B21: =IFERROR(INDEX(MASTER_REGISTER!C:C,MATCH(C21,MASTER_REGISTER!E:E,0)),"") -> 9 | C21: MSH202609008 | D21: =IFERROR(INDEX(MASTER_REGISTER!F:F,MATCH(C21,MASTER_REGISTER!E:E,0)),"") -> Sifiso Ramushu | E21: Present | F21: 07:05 | G21: 15:00
A22: 2026-01-03 | B22: =IFERROR(INDEX(MASTER_REGISTER!C:C,MATCH(C22,MASTER_REGISTER!E:E,0)),"") -> 9 | C22: MSH202609009 | D22: =IFERROR(INDEX(MASTER_REGISTER!F:F,MATCH(C22,MASTER_REGISTER!E:E,0)),"") -> Nandi Ngobeni | E22: Present | F22: 07:05 | G22: 15:00
A23: 2026-01-03 | B23: =IFERROR(INDEX(MASTER_REGISTER!C:C,MATCH(C23,MASTER_REGISTER!E:E,0)),"") -> 9 | C23: MSH202609010 | D23: =IFERROR(INDEX(MASTER_REGISTER!F:F,MATCH(C23,MASTER_REGISTER!E:E,0)),"") -> Karabo Mokgadi | E23: Present | F23: 07:05 | G23: 15:00
A24: 2026-01-03 | B24: =IFERROR(INDEX(MASTER_REGISTER!C:C,MATCH(C24,MASTER_REGISTER!E:E,0)),"") -> 9 | C24: MSH202609011 | D24: =IFERROR(INDEX(MASTER_REGISTER!F:F,MATCH(C24,MASTER_REGISTER!E:E,0)),"") -> Sifiso Mahlangu | E24: Present | F24: 07:05 | G24: 15:00
A25: 2026-01-03 | B25: =IFERROR(INDEX(MASTER_REGISTER!C:C,MATCH(C25,MASTER_REGISTER!E:E,0)),"") -> 9 | C25: MSH202609012 | D25: =IFERROR(INDEX(MASTER_REGISTER!F:F,MATCH(C25,MASTER_REGISTER!E:E,0)),"") -> Kgothatso Radebe | E25: Present | F25: 07:05 | G25: 15:00
A26: 2026-01-03 | B26: =IFERROR(INDEX(MASTER_REGISTER!C:C,MATCH(C26,MASTER_REGISTER!E:E,0)),"") -> 10 | C26: MSH202610001 | D26: =IFERROR(INDEX(MASTER_REGISTER!F:F,MATCH(C26,MASTER_REGISTER!E:E,0)),"") -> Lerato Maseko | E26: Present | F26: 07:05 | G26: 15:00
... A33: 2026-01-03 | B33: =IFERROR(INDEX(MASTER_REGISTER!C:C,MATCH(C33,MASTER_REGISTER!E:E,0)),"") -> 10 | C33: MSH202610008 | D33: =IFERROR(INDEX(MASTER_REGISTER!F:F,MATCH(C33,MASTER_REGISTER!E:E,0)),"") -> Mpho Ngobeni | E33: Present | F33: 07:05 | G33: 15:00
A34: 2026-01-03 | B34: =IFERROR(INDEX(MASTER_REGISTER!C:C,MATCH(C34,MASTER_REGISTER!E:E,0)),"") -> 10 | C34: MSH202610009 | D34: =IFERROR(INDEX(MASTER_REGISTER!F:F,MATCH(C34,MASTER_REGISTER!E:E,0)),"") -> Naledi Makhubela | E34: Absent | H34: Sick
A35: 2026-01-03 | B35: =IFERROR(INDEX(MASTER_REGISTER!C:C,MATCH(C35,MASTER_REGISTER!E:E,0)),"") -> 10 | C35: MSH202610010 | D35: =IFERROR(INDEX(MASTER_REGISTER!F:F,MATCH(C35,MASTER_REGISTER!E:E,0)),"") -> Kgothatso Mokoena | E35: Present | F35: 07:05 | G35: 15:00
A36: 2026-01-03 | B36: =IFERROR(INDEX(MASTER_REGISTER!C:C,MATCH(C36,MASTER_REGISTER!E:E,0)),"") -> 10 | C36: MSH202610011 | D36: =IFERROR(INDEX(MASTER_REGISTER!F:F,MATCH(C36,MASTER_REGISTER!E:E,0)),"") -> Bongani Makhubela | E36: Present | F36: 07:05 | G36: 15:00
A37: 2026-01-03 | B37: =IFERROR(INDEX(MASTER_REGISTER!C:C,MATCH(C37,MASTER_REGISTER!E:E,0)),"") -> 10 | C37: MSH202610012 | D37: =IFERROR(INDEX(MASTER_REGISTER!F:F,MATCH(C37,MASTER_REGISTER!E:E,0)),"") -> Kagiso Kekana | E37: Present | F37: 07:05 | G37: 15:00
A38: 2026-01-03 | B38: =IFERROR(INDEX(MASTER_REGISTER!C:C,MATCH(C38,MASTER_REGISTER!E:E,0)),"") -> 11 | C38: MSH202611001 | D38: =IFERROR(INDEX(MASTER_REGISTER!F:F,MATCH(C38,MASTER_REGISTER!E:E,0)),"") -> Lwazi Makhubela | E38: Present | F38: 07:05 | G38: 15:00
A39: 2026-01-03 | B39: =IFERROR(INDEX(MASTER_REGISTER!C:C,MATCH(C39,MASTER_REGISTER!E:E,0)),"") -> 11 | C39: MSH202611002 | D39: =IFERROR(INDEX(MASTER_REGISTER!F:F,MATCH(C39,MASTER_REGISTER!E:E,0)),"") -> Lebogang Ramushu | E39: Present | F39: 07:05 | G39: 15:00
A40: 2026-01-03 | B40: =IFERROR(INDEX(MASTER_REGISTER!C:C,MATCH(C40,MASTER_REGISTER!E:E,0)),"") -> 11 | C40: MSH202611003 | D40: =IFERROR(INDEX(MASTER_REGISTER!F:F,MATCH(C40,MASTER_REGISTER!E:E,0)),"") -> Lerato Kekana | E40: Present | F40: 07:05 | G40: 15:00
A41: 2026-01-03 | B41: =IFERROR(INDEX(MASTER_REGISTER!C:C,MATCH(C41,MASTER_REGISTER!E:E,0)),"") -> 11 | C41: MSH202611004 | D41: =IFERROR(INDEX(MASTER_REGISTER!F:F,MATCH(C41,MASTER_REGISTER!E:E,0)),"") -> Bongani Ndlovu | E41: Present | F41: 07:05 | G41: 15:00
A42: 2026-01-03 | B42: =IFERROR(INDEX(MASTER_REGISTER!C:C,MATCH(C42,MASTER_REGISTER!E:E,0)),"") -> 11 | C42: MSH202611005 | D42: =IFERROR(INDEX(MASTER_REGISTER!F:F,MATCH(C42,MASTER_REGISTER!E:E,0)),"") -> Sifiso Dlamini | E42: Present | F42: 07:05 | G42: 15:00
A43: 2026-01-03 | B43: =IFERROR(INDEX(MASTER_REGISTER!C:C,MATCH(C43,MASTER_REGISTER!E:E,0)),"") -> 11 | C43: MSH202611006 | D43: =IFERROR(INDEX(MASTER_REGISTER!F:F,MATCH(C43,MASTER_REGISTER!E:E,0)),"") -> Refilwe Dlamini | E43: Present | F43: 07:05 | G43: 15:00
A44: 2026-01-03 | B44: =IFERROR(INDEX(MASTER_REGISTER!C:C,MATCH(C44,MASTER_REGISTER!E:E,0)),"") -> 11 | C44: MSH202611007 | D44: =IFERROR(INDEX(MASTER_REGISTER!F:F,MATCH(C44,MASTER_REGISTER!E:E,0)),"") -> Lwazi Maseko | E44: Present | F44: 07:05 | G44: 15:00
A45: 2026-01-03 | B45: =IFERROR(INDEX(MASTER_REGISTER!C:C,MATCH(C45,MASTER_REGISTER!E:E,0)),"") -> 11 | C45: MSH202611008 | D45: =IFERROR(INDEX(MASTER_REGISTER!F:F,MATCH(C45,MASTER_REGISTER!E:E,0)),"") -> Refilwe Mokgadi | E45: Present | F45: 07:05 | G45: 15:00
A46: 2026-01-03 | B46: =IFERROR(INDEX(MASTER_REGISTER!C:C,MATCH(C46,MASTER_REGISTER!E:E,0)),"") -> 11 | C46: MSH202611009 | D46: =IFERROR(INDEX(MASTER_REGISTER!F:F,MATCH(C46,MASTER_REGISTER!E:E,0)),"") -> Kgothatso Molefe | E46: Absent | H46: Sick
...

Sheet ATTENDANCE_SUMMARY
A1: Student Number | B1: Learner Name | C1: Grade | D1: Sessions Recorded | E1: Days Present | F1: Days Absent | G1: Attendance % | H1: Attendance Flag
A2: =IF(MASTER_REGISTER!E2="","",MASTER_REGISTER!E2) -> MSH202608001 | B2: =IF(A2="","",MASTER_REGISTER!F2) -> Lerato Nkosi | C2: =IF(A2="","",MASTER_REGISTER!C2) -> 8 | D2: =IF(A2="","",COUNTIF(ATTENDANCE_DAILY!C:C,A2)) -> 48 | E2: =IF(A2="","",COUNTIFS(ATTENDANCE_DAILY!C:C,A2,ATTENDANCE_DAILY!E:E,"Present")) -> 39 | F2: =IF(A2="","",COUNTIFS(ATTENDANCE_DAILY!C:C,A2,ATTENDANCE_DAILY!E:E,"Absent")) -> 9 | G2: =IF(D2=0,"",E2/D2) -> 0.8125 | H2: =IF(G2="","",IF(G2<0.75,"Low Attendance","OK")) -> OK
A3: =IF(MASTER_REGISTER!E3="","",MASTER_REGISTER!E3) -> MSH202608002 | B3: =IF(A3="","",MASTER_REGISTER!F3) -> Karabo Maseko | C3: =IF(A3="","",MASTER_REGISTER!C3) -> 8 | D3: =IF(A3="","",COUNTIF(ATTENDANCE_DAILY!C:C,A3)) -> 48 | E3: =IF(A3="","",COUNTIFS(ATTENDANCE_DAILY!C:C,A3,ATTENDANCE_DAILY!E:E,"Present")) -> 40 | F3: =IF(A3="","",COUNTIFS(ATTENDANCE_DAILY!C:C,A3,ATTENDANCE_DAILY!E:E,"Absent")) -> 8 | G3: =IF(D3=0,"",E3/D3) -> 0.83333333 | H3: =IF(G3="","",IF(G3<0.75,"Low Attendance","OK")) -> OK
A4: =IF(MASTER_REGISTER!E4="","",MASTER_REGISTER!E4) -> MSH202608003 | B4: =IF(A4="","",MASTER_REGISTER!F4) -> Sifiso Sithole | C4: =IF(A4="","",MASTER_REGISTER!C4) -> 8 | D4: =IF(A4="","",COUNTIF(ATTENDANCE_DAILY!C:C,A4)) -> 48 | E4: =IF(A4="","",COUNTIFS(ATTENDANCE_DAILY!C:C,A4,ATTENDANCE_DAILY!E:E,"Present")) -> 44 | F4: =IF(A4="","",COUNTIFS(ATTENDANCE_DAILY!C:C,A4,ATTENDANCE_DAILY!E:E,"Absent")) -> 4 | G4: =IF(D4=0,"",E4/D4) -> 0.91666667 | H4: =IF(G4="","",IF(G4<0.75,"Low Attendance","OK")) -> OK
A5: =IF(MASTER_REGISTER!E5="","",MASTER_REGISTER!E5) -> MSH202608004 | B5: =IF(A5="","",MASTER_REGISTER!F5) -> Tshepo Ndlovu | C5: =IF(A5="","",MASTER_REGISTER!C5) -> 8 | D5: =IF(A5="","",COUNTIF(ATTENDANCE_DAILY!C:C,A5)) -> 48 | E5: =IF(A5="","",COUNTIFS(ATTENDANCE_DAILY!C:C,A5,ATTENDANCE_DAILY!E:E,"Present")) -> 45 | F5: =IF(A5="","",COUNTIFS(ATTENDANCE_DAILY!C:C,A5,ATTENDANCE_DAILY!E:E,"Absent")) -> 3 | G5: =IF(D5=0,"",E5/D5) -> 0.9375 | H5: =IF(G5="","",IF(G5<0.75,"Low Attendance","OK")) -> OK
A6: =IF(MASTER_REGISTER!E6="","",MASTER_REGISTER!E6) -> MSH202608005 | B6: =IF(A6="","",MASTER_REGISTER!F6) -> Lwazi Mthembu | C6: =IF(A6="","",MASTER_REGISTER!C6) -> 8 | D6: =IF(A6="","",COUNTIF(ATTENDANCE_DAILY!C:C,A6)) -> 48 | E6: =IF(A6="","",COUNTIFS(ATTENDANCE_DAILY!C:C,A6,ATTENDANCE_DAILY!E:E,"Present")) -> 41 | F6: =IF(A6="","",COUNTIFS(ATTENDANCE_DAILY!C:C,A6,ATTENDANCE_DAILY!E:E,"Absent")) -> 7 | G6: =IF(D6=0,"",E6/D6) -> 0.85416667 | H6: =IF(G6="","",IF(G6<0.75,"Low Attendance","OK")) -> OK
A7: =IF(MASTER_REGISTER!E7="","",MASTER_REGISTER!E7) -> MSH202608006 | B7: =IF(A7="","",MASTER_REGISTER!F7) -> Karabo Ngobeni | C7: =IF(A7="","",MASTER_REGISTER!C7) -> 8 | D7: =IF(A7="","",COUNTIF(ATTENDANCE_DAILY!C:C,A7)) -> 48 | E7: =IF(A7="","",COUNTIFS(ATTENDANCE_DAILY!C:C,A7,ATTENDANCE_DAILY!E:E,"Present")) -> 42 | F7: =IF(A7="","",COUNTIFS(ATTENDANCE_DAILY!C:C,A7,ATTENDANCE_DAILY!E:E,"Absent")) -> 6 | G7: =IF(D7=0,"",E7/D7) -> 0.875 | H7: =IF(G7="","",IF(G7<0.75,"Low Attendance","OK")) -> OK
A8: =IF(MASTER_REGISTER!E8="","",MASTER_REGISTER!E8) -> MSH202608007 | B8: =IF(A8="","",MASTER_REGISTER!F8) -> Mpho Sithole | C8: =IF(A8="","",MASTER_REGISTER!C8) -> 8 | D8: =IF(A8="","",COUNTIF(ATTENDANCE_DAILY!C:C,A8)) -> 48 | E8: =IF(A8="","",COUNTIFS(ATTENDANCE_DAILY!C:C,A8,ATTENDANCE_DAILY!E:E,"Present")) -> 44 | F8: =IF(A8="","",COUNTIFS(ATTENDANCE_DAILY!C:C,A8,ATTENDANCE_DAILY!E:E,"Absent")) -> 4 | G8: =IF(D8=0,"",E8/D8) -> 0.91666667 | H8: =IF(G8="","",IF(G8<0.75,"Low Attendance","OK")) -> OK
A9: =IF(MASTER_REGISTER!E9="","",MASTER_REGISTER!E9) -> MSH202608008 | B9: =IF(A9="","",MASTER_REGISTER!F9) -> Tshepo Ramushu | C9: =IF(A9="","",MASTER_REGISTER!C9) -> 8 | D9: =IF(A9="","",COUNTIF(ATTENDANCE_DAILY!C:C,A9)) -> 48 | E9: =IF(A9="","",COUNTIFS(ATTENDANCE_DAILY!C:C,A9,ATTENDANCE_DAILY!E:E,"Present")) -> 42 | F9: =IF(A9="","",COUNTIFS(ATTENDANCE_DAILY!C:C,A9,ATTENDANCE_DAILY!E:E,"Absent")) -> 6 | G9: =IF(D9=0,"",E9/D9) -> 0.875 | H9: =IF(G9="","",IF(G9<0.75,"Low Attendance","OK")) -> OK
A10: =IF(MASTER_REGISTER!E10="","",MASTER_REGISTER!E10) -> MSH202608009 | B10: =IF(A10="","",MASTER_REGISTER!F10) -> Lerato Kekana | C10: =IF(A10="","",MASTER_REGISTER!C10) -> 8 | D10: =IF(A10="","",COUNTIF(ATTENDANCE_DAILY!C:C,A10)) -> 48 | E10: =IF(A10="","",COUNTIFS(ATTENDANCE_DAILY!C:C,A10,ATTENDANCE_DAILY!E:E,"Present")) -> 46 | F10: =IF(A10="","",COUNTIFS(ATTENDANCE_DAILY!C:C,A10,ATTENDANCE_DAILY!E:E,"Absent")) -> 2 | G10: =IF(D10=0,"",E10/D10) -> 0.95833333 | H10: =IF(G10="","",IF(G10<0.75,"Low Attendance","OK")) -> OK
A11: =IF(MASTER_REGISTER!E11="","",MASTER_REGISTER!E11) -> MSH202608010 | B11: =IF(A11="","",MASTER_REGISTER!F11) -> Neo Ngobeni | C11: =IF(A11="","",MASTER_REGISTER!C11) -> 8 | D11: =IF(A11="","",COUNTIF(ATTENDANCE_DAILY!C:C,A11)) -> 48 | E11: =IF(A11="","",COUNTIFS(ATTENDANCE_DAILY!C:C,A11,ATTENDANCE_DAILY!E:E,"Present")) -> 44 | F11: =IF(A11="","",COUNTIFS(ATTENDANCE_DAILY!C:C,A11,ATTENDANCE_DAILY!E:E,"Absent")) -> 4 | G11: =IF(D11=0,"",E11/D11) -> 0.91666667 | H11: =IF(G11="","",IF(G11<0.75,"Low Attendance","OK")) -> OK
A12: =IF(MASTER_REGISTER!E12="","",MASTER_REGISTER!E12) -> MSH202608011 | B12: =IF(A12="","",MASTER_REGISTER!F12) -> Thabo Mokgadi | C12: =IF(A12="","",MASTER_REGISTER!C12) -> 8 | D12: =IF(A12="","",COUNTIF(ATTENDANCE_DAILY!C:C,A12)) -> 48 | E12: =IF(A12="","",COUNTIFS(ATTENDANCE_DAILY!C:C,A12,ATTENDANCE_DAILY!E:E,"Present")) -> 42 | F12: =IF(A12="","",COUNTIFS(ATTENDANCE_DAILY!C:C,A12,ATTENDANCE_DAILY!E:E,"Absent")) -> 6 | G12: =IF(D12=0,"",E12/D12) -> 0.875 | H12: =IF(G12="","",IF(G12<0.75,"Low Attendance","OK")) -> OK
A13: =IF(MASTER_REGISTER!E13="","",MASTER_REGISTER!E13) -> MSH202608012 | B13: =IF(A13="","",MASTER_REGISTER!F13) -> Sifiso Mthembu | C13: =IF(A13="","",MASTER_REGISTER!C13) -> 8 | D13: =IF(A13="","",COUNTIF(ATTENDANCE_DAILY!C:C,A13)) -> 48 | E13: =IF(A13="","",COUNTIFS(ATTENDANCE_DAILY!C:C,A13,ATTENDANCE_DAILY!E:E,"Present")) -> 42 | F13: =IF(A13="","",COUNTIFS(ATTENDANCE_DAILY!C:C,A13,ATTENDANCE_DAILY!E:E,"Absent")) -> 6 | G13: =IF(D13=0,"",E13/D13) -> 0.875 | H13: =IF(G13="","",IF(G13<0.75,"Low Attendance","OK")) -> OK
... A501: =IF(MASTER_REGISTER!E501="","",MASTER_REGISTER!E501) | B501: =IF(A501="","",MASTER_REGISTER!F501) | C501: =IF(A501="","",MASTER_REGISTER!C501) | D501: =IF(A501="","",COUNTIF(ATTENDANCE_DAILY!C:C,A501)) | E501: =IF(A501="","",COUNTIFS(ATTENDANCE_DAILY!C:C,A501,ATTENDANCE_DAILY!E:E,"Present")) | F501: =IF(A501="","",COUNTIFS(ATTENDANCE_DAILY!C:C,A501,ATTENDANCE_DAILY!E:E,"Absent")) | G501: =IF(D501=0,"",E501/D501) -> #VALUE! | H501: =IF(G501="","",IF(G501<0.75,"Low Attendance","OK")) -> #VALUE!

Sheet PAYMENTS
A1: Payment Date | B1: Receipt/Ref | C1: Student Number | D1: Payer Name | E1: Amount Paid (R) | F1: Method | G1: Notes
A2: 2026-02-10 | B2: MSH-R1001 | C2: MSH202608001 | D2: Lerato Nkosi | E2: 316.93 | F2: Cash | G2: Term payment 2
A3: 2026-03-05 | B3: MSH-R1002 | C3: MSH202608001 | D3: Lerato Nkosi | E3: 185.38 | F3: Card | G3: Term payment 3
A4: 2026-07-15 | B4: MSH-R1003 | C4: MSH202608001 | D4: Lerato Nkosi | E4: 174.28 | F4: Cash | G4: Term payment 7
A5: 2026-08-10 | B5: MSH-R1004 | C5: MSH202608001 | D5: Lerato Nkosi | E5: 243.93 | F5: Cash | G5: Term payment 8
A6: 2026-02-05 | B6: MSH-R1005 | C6: MSH202608002 | D6: Karabo Maseko | E6: 179.92 | F6: EFT | G6: Term payment 2
A7: 2026-03-15 | B7: MSH-R1006 | C7: MSH202608002 | D7: Karabo Maseko | E7: 190.17 | F7: EFT | G7: Term payment 3
A8: 2026-06-01 | B8: MSH-R1007 | C8: MSH202608002 | D8: Karabo Maseko | E8: 179.56 | F8: Cash | G8: Term payment 6
A9: 2026-07-15 | B9: MSH-R1008 | C9: MSH202608002 | D9: Karabo Maseko | E9: 201.28 | F9: EFT | G9: Term payment 7
A10: 2026-08-10 | B10: MSH-R1009 | C10: MSH202608002 | D10: Karabo Maseko | E10: 235.37 | F10: Card | G10: Term payment 8
A11: 2026-09-20 | B11: MSH-R1010 | C11: MSH202608002 | D11: Karabo Maseko | E11: 286.96 | F11: EFT | G11: Term payment 9
A12: 2026-10-05 | B12: MSH-R1011 | C12: MSH202608002 | D12: Karabo Maseko | E12: 185.02 | F12: Cash | G12: Term payment 10
A13: 2026-02-10 | B13: MSH-R1012 | C13: MSH202608003 | D13: Sifiso Sithole | E13: 156.35 | F13: Card | G13: Term payment 2
... A363: 2026-11-05 | B363: MSH-R1362 | C363: MSH202612012 | D363: Sibusiso Ngobeni | E363: 253.66 | F363: EFT | G363: Term payment 11

Sheet ASSESSMENTS
A1: Assessment Date | B1: Student Number | C1: Learner Name (auto) | D1: Grade (auto) | E1: Subject | F1: Assessment Type | G1: Topic | H1: Score (%) | I1: Tutor | J1: Notes
A2: 2026-03-05 | B2: MSH202608001 | C2: =IFERROR(_xludf.XLOOKUP(B2,MASTER_REGISTER!E:E,MASTER_REGISTER!F:F,""),"") | D2: =IFERROR(_xludf.XLOOKUP(B2,MASTER_REGISTER!E:E,MASTER_REGISTER!C:C,""),"") | E2: Mathematics | F2: Monthly Test | G2: Algebra | H2: 66.1 | I2: S. Radebe
A3: 2026-03-26 | B3: MSH202608001 | C3: =IFERROR(_xludf.XLOOKUP(B3,MASTER_REGISTER!E:E,MASTER_REGISTER!F:F,""),"") | D3: =IFERROR(_xludf.XLOOKUP(B3,MASTER_REGISTER!E:E,MASTER_REGISTER!C:C,""),"") | E3: Mathematics | F3: Monthly Test | G3: Financial Maths | H3: 52.4 | I3: P. Phiri
A4: 2026-05-12 | B4: MSH202608001 | C4: =IFERROR(_xludf.XLOOKUP(B4,MASTER_REGISTER!E:E,MASTER_REGISTER!F:F,""),"") | D4: =IFERROR(_xludf.XLOOKUP(B4,MASTER_REGISTER!E:E,MASTER_REGISTER!C:C,""),"") | E4: EMS | F4: Class Test | G4: Kinematics | H4: 67.7 | I4: M. Nkosi
A5: 2026-05-26 | B5: MSH202608001 | C5: =IFERROR(_xludf.XLOOKUP(B5,MASTER_REGISTER!E:E,MASTER_REGISTER!F:F,""),"") | D5: =IFERROR(_xludf.XLOOKUP(B5,MASTER_REGISTER!E:E,MASTER_REGISTER!C:C,""),"") | E5: EMS | F5: Class Test | G5: Maps | H5: 44.6 | I5: M. Nkosi
A6: 2026-06-05 | B6: MSH202608001 | C6: =IFERROR(_xludf.XLOOKUP(B6,MASTER_REGISTER!E:E,MASTER_REGISTER!F:F,""),"") | D6: =IFERROR(_xludf.XLOOKUP(B6,MASTER_REGISTER!E:E,MASTER_REGISTER!C:C,""),"") | E6: Natural Sciences & Technology | F6: Homework Test | G6: Financial Maths | H6: 59.5 | I6: M. Nkosi
A7: 2026-06-12 | B7: MSH202608001 | C7: =IFERROR(_xludf.XLOOKUP(B7,MASTER_REGISTER!E:E,MASTER_REGISTER!F:F,""),"") | D7: =IFERROR(_xludf.XLOOKUP(B7,MASTER_REGISTER!E:E,MASTER_REGISTER!C:C,""),"") | E7: EMS | F7: Term Exam | G7: Statistics | H7: 67.9 | I7: S. Radebe
A8: 2026-08-19 | B8: MSH202608001 | C8: =IFERROR(_xludf.XLOOKUP(B8,MASTER_REGISTER!E:E,MASTER_REGISTER!F:F,""),"") | D8: =IFERROR(_xludf.XLOOKUP(B8,MASTER_REGISTER!E:E,MASTER_REGISTER!C:C,""),"") | E8: English | F8: Term Exam | G8: Maps | H8: 69.5 | I8: K. Maseko
A9: 2026-08-19 | B9: MSH202608001 | C9: =IFERROR(_xludf.XLOOKUP(B9,MASTER_REGISTER!E:E,MASTER_REGISTER!F:F,""),"") | D9: =IFERROR(_xludf.XLOOKUP(B9,MASTER_REGISTER!E:E,MASTER_REGISTER!C:C,""),"") | E9: Mathematics | F9: Term Exam | G9: Statistics | H9: 61.4 | I9: M. Nkosi
A10: 2026-09-26 | B10: MSH202608001 | C10: =IFERROR(_xludf.XLOOKUP(B10,MASTER_REGISTER!E:E,MASTER_REGISTER!F:F,""),"") | D10: =IFERROR(_xludf.XLOOKUP(B10,MASTER_REGISTER!E:E,MASTER_REGISTER!C:C,""),"") | E10: EMS | F10: Monthly Test | G10: Functions | H10: 57.7 | I10: L. Mahlangu
A11: 2026-11-19 | B11: MSH202608001 | C11: =IFERROR(_xludf.XLOOKUP(B11,MASTER_REGISTER!E:E,MASTER_REGISTER!F:F,""),"") | D11: =IFERROR(_xludf.XLOOKUP(B11,MASTER_REGISTER!E:E,MASTER_REGISTER!C:C,""),"") | E11: English | F11: Term Exam | G11: Mechanics | H11: 75.6 | I11: T. Dlamini
A12: 2026-02-19 | B12: MSH202608002 | C12: =IFERROR(_xludf.XLOOKUP(B12,MASTER_REGISTER!E:E,MASTER_REGISTER!F:F,""),"") | D12: =IFERROR(_xludf.XLOOKUP(B12,MASTER_REGISTER!E:E,MASTER_REGISTER!C:C,""),"") | E12: English | F12: Monthly Test | G12: Statistics | H12: 77.4 | I12: L. Mahlangu
A13: 2026-03-26 | B13: MSH202608002 | C13: =IFERROR(_xludf.XLOOKUP(B13,MASTER_REGISTER!E:E,MASTER_REGISTER!F:F,""),"") | D13: =IFERROR(_xludf.XLOOKUP(B13,MASTER_REGISTER!E:E,MASTER_REGISTER!C:C,""),"") | E13: EMS | F13: Class Test | G13: Kinematics | H13: 48.5 | I13: T. Dlamini
... A601: 2026-10-26 | B601: MSH202612012 | C601: =IFERROR(_xludf.XLOOKUP(B601,MASTER_REGISTER!E:E,MASTER_REGISTER!F:F,""),"") | D601: =IFERROR(_xludf.XLOOKUP(B601,MASTER_REGISTER!E:E,MASTER_REGISTER!C:C,""),"") | E601: Physical Sciences | F601: Monthly Test | G601: Trigonometry | H601: 77.4 | I601: N. Mokoena
C602: =IFERROR(_xludf.XLOOKUP(B602,MASTER_REGISTER!E:E,MASTER_REGISTER!F:F,""),"") | D602: =IFERROR(_xludf.XLOOKUP(B602,MASTER_REGISTER!E:E,MASTER_REGISTER!C:C,""),"")

Sheet PROGRESS_SUMMARY
A1: Student Number | B1: Learner Name | C1: Grade | D1: Assessments Logged | E1: Average Score (%) | F1: Math Avg | G1: Math Lit Avg | H1: Physical Sciences Avg | I1: Geography Avg | J1: Accounting Avg | K1: English Avg | L1: Attendance % (auto) | M1: Progress Flag
A2: =IF(MASTER_REGISTER!E2="","",MASTER_REGISTER!E2) -> MSH202608001 | B2: =IF(A2="","",MASTER_REGISTER!F2) -> Lerato Nkosi | C2: =IF(A2="","",MASTER_REGISTER!C2) -> 8 | D2: =IF(A2="","",COUNTIF(ASSESSMENTS!B:B,A2)) -> 10 | E2: =IF(D2=0,"",ROUND(AVERAGEIF(ASSESSMENTS!B:B,A2,ASSESSMENTS!H:H),1)) -> 62.2 | F2: =IF(A2="","",IFERROR(ROUND(AVERAGEIFS(ASSESSMENTS!H:H,ASSESSMENTS!B:B,A2,ASSESSMENTS!E:E,"Mathematics"),1),"")) -> 60 | G2: =IF(A2="","",IFERROR(ROUND(AVERAGEIFS(ASSESSMENTS!H:H,ASSESSMENTS!B:B,A2,ASSESSMENTS!E:E,"Mathematical Literacy"),1),"")) | H2: =IF(A2="","",IFERROR(ROUND(AVERAGEIFS(ASSESSMENTS!H:H,ASSESSMENTS!B:B,A2,ASSESSMENTS!E:E,"Physical Sciences"),1),"")) | I2: =IF(A2="","",IFERROR(ROUND(AVERAGEIFS(ASSESSMENTS!H:H,ASSESSMENTS!B:B,A2,ASSESSMENTS!E:E,"Geography"),1),"")) | J2: =IF(A2="","",IFERROR(ROUND(AVERAGEIFS(ASSESSMENTS!H:H,ASSESSMENTS!B:B,A2,ASSESSMENTS!E:E,"Accounting"),1),"")) | K2: =IF(A2="","",IFERROR(ROUND(AVERAGEIFS(ASSESSMENTS!H:H,ASSESSMENTS!B:B,A2,ASSESSMENTS!E:E,"English"),1),"")) -> 72.6 | L2: =IF(A2="","",IFERROR(INDEX(ATTENDANCE_SUMMARY!G:G,MATCH(A2,ATTENDANCE_SUMMARY!A:A,0)),"")) -> 0.8125 | M2: =IF(A2="","",IF(OR(E2<50,AND(L2<0.75,L2<>"" )),"At Risk","On Track")) -> On Track
A3: =IF(MASTER_REGISTER!E3="","",MASTER_REGISTER!E3) -> MSH202608002 | B3: =IF(A3="","",MASTER_REGISTER!F3) -> Karabo Maseko | C3: =IF(A3="","",MASTER_REGISTER!C3) -> 8 | D3: =IF(A3="","",COUNTIF(ASSESSMENTS!B:B,A3)) -> 10 | E3: =IF(D3=0,"",ROUND(AVERAGEIF(ASSESSMENTS!B:B,A3,ASSESSMENTS!H:H),1)) -> 64.2 | F3: =IF(A3="","",IFERROR(ROUND(AVERAGEIFS(ASSESSMENTS!H:H,ASSESSMENTS!B:B,A3,ASSESSMENTS!E:E,"Mathematics"),1),"")) | G3: =IF(A3="","",IFERROR(ROUND(AVERAGEIFS(ASSESSMENTS!H:H,ASSESSMENTS!B:B,A3,ASSESSMENTS!E:E,"Mathematical Literacy"),1),"")) | H3: =IF(A3="","",IFERROR(ROUND(AVERAGEIFS(ASSESSMENTS!H:H,ASSESSMENTS!B:B,A3,ASSESSMENTS!E:E,"Physical Sciences"),1),"")) | I3: =IF(A3="","",IFERROR(ROUND(AVERAGEIFS(ASSESSMENTS!H:H,ASSESSMENTS!B:B,A3,ASSESSMENTS!E:E,"Geography"),1),"")) | J3: =IF(A3="","",IFERROR(ROUND(AVERAGEIFS(ASSESSMENTS!H:H,ASSESSMENTS!B:B,A3,ASSESSMENTS!E:E,"Accounting"),1),"")) | K3: =IF(A3="","",IFERROR(ROUND(AVERAGEIFS(ASSESSMENTS!H:H,ASSESSMENTS!B:B,A3,ASSESSMENTS!E:E,"English"),1),"")) -> 62.3 | L3: =IF(A3="","",IFERROR(INDEX(ATTENDANCE_SUMMARY!G:G,MATCH(A3,ATTENDANCE_SUMMARY!A:A,0)),"")) -> 0.83333333 | M3: =IF(A3="","",IF(OR(E3<50,AND(L3<0.75,L3<>"" )),"At Risk","On Track")) -> On Track
A4: =IF(MASTER_REGISTER!E4="","",MASTER_REGISTER!E4) -> MSH202608003 | B4: =IF(A4="","",MASTER_REGISTER!F4) -> Sifiso Sithole | C4: =IF(A4="","",MASTER_REGISTER!C4) -> 8 | D4: =IF(A4="","",COUNTIF(ASSESSMENTS!B:B,A4)) -> 10 | E4: =IF(D4=0,"",ROUND(AVERAGEIF(ASSESSMENTS!B:B,A4,ASSESSMENTS!H:H),1)) -> 59 | F4: =IF(A4="","",IFERROR(ROUND(AVERAGEIFS(ASSESSMENTS!H:H,ASSESSMENTS!B:B,A4,ASSESSMENTS!E:E,"Mathematics"),1),"")) | G4: =IF(A4="","",IFERROR(ROUND(AVERAGEIFS(ASSESSMENTS!H:H,ASSESSMENTS!B:B,A4,ASSESSMENTS!E:E,"Mathematical Literacy"),1),"")) | H4: =IF(A4="","",IFERROR(ROUND(AVERAGEIFS(ASSESSMENTS!H:H,ASSESSMENTS!B:B,A4,ASSESSMENTS!E:E,"Physical Sciences"),1),"")) | I4: =IF(A4="","",IFERROR(ROUND(AVERAGEIFS(ASSESSMENTS!H:H,ASSESSMENTS!B:B,A4,ASSESSMENTS!E:E,"Geography"),1),"")) | J4: =IF(A4="","",IFERROR(ROUND(AVERAGEIFS(ASSESSMENTS!H:H,ASSESSMENTS!B:B,A4,ASSESSMENTS!E:E,"Accounting"),1),"")) | K4: =IF(A4="","",IFERROR(ROUND(AVERAGEIFS(ASSESSMENTS!H:H,ASSESSMENTS!B:B,A4,ASSESSMENTS!E:E,"English"),1),"")) -> 53.9 | L4: =IF(A4="","",IFERROR(INDEX(ATTENDANCE_SUMMARY!G:G,MATCH(A4,ATTENDANCE_SUMMARY!A:A,0)),"")) -> 0.91666667 | M4: =IF(A4="","",IF(OR(E4<50,AND(L4<0.75,L4<>"" )),"At Risk","On Track")) -> On Track
A5: =IF(MASTER_REGISTER!E5="","",MASTER_REGISTER!E5) -> MSH202608004 | B5: =IF(A5="","",MASTER_REGISTER!F5) -> Tshepo Ndlovu | C5: =IF(A5="","",MASTER_REGISTER!C5) -> 8 | D5: =IF(A5="","",COUNTIF(ASSESSMENTS!B:B,A5)) -> 10 | E5: =IF(D5=0,"",ROUND(AVERAGEIF(ASSESSMENTS!B:B,A5,ASSESSMENTS!H:H),1)) -> 66.3 | F5: =IF(A5="","",IFERROR(ROUND(AVERAGEIFS(ASSESSMENTS!H:H,ASSESSMENTS!B:B,A5,ASSESSMENTS!E:E,"Mathematics"),1),"")) -> 61.7 | G5: =IF(A5="","",IFERROR(ROUND(AVERAGEIFS(ASSESSMENTS!H:H,ASSESSMENTS!B:B,A5,ASSESSMENTS!E:E,"Mathematical Literacy"),1),"")) | H5: =IF(A5="","",IFERROR(ROUND(AVERAGEIFS(ASSESSMENTS!H:H,ASSESSMENTS!B:B,A5,ASSESSMENTS!E:E,"Physical Sciences"),1),"")) | I5: =IF(A5="","",IFERROR(ROUND(AVERAGEIFS(ASSESSMENTS!H:H,ASSESSMENTS!B:B,A5,ASSESSMENTS!E:E,"Geography"),1),"")) | J5: =IF(A5="","",IFERROR(ROUND(AVERAGEIFS(ASSESSMENTS!H:H,ASSESSMENTS!B:B,A5,ASSESSMENTS!E:E,"Accounting"),1),"")) | K5: =IF(A5="","",IFERROR(ROUND(AVERAGEIFS(ASSESSMENTS!H:H,ASSESSMENTS!B:B,A5,ASSESSMENTS!E:E,"English"),1),"")) -> 68.1 | L5: =IF(A5="","",IFERROR(INDEX(ATTENDANCE_SUMMARY!G:G,MATCH(A5,ATTENDANCE_SUMMARY!A:A,0)),"")) -> 0.9375 | M5: =IF(A5="","",IF(OR(E5<50,AND(L5<0.75,L5<>"" )),"At Risk","On Track")) -> On Track
A6: =IF(MASTER_REGISTER!E6="","",MASTER_REGISTER!E6) -> MSH202608005 | B6: =IF(A6="","",MASTER_REGISTER!F6) -> Lwazi Mthembu | C6: =IF(A6="","",MASTER_REGISTER!C6) -> 8 | D6: =IF(A6="","",COUNTIF(ASSESSMENTS!B:B,A6)) -> 10 | E6: =IF(D6=0,"",ROUND(AVERAGEIF(ASSESSMENTS!B:B,A6,ASSESSMENTS!H:H),1)) -> 64.6 | F6: =IF(A6="","",IFERROR(ROUND(AVERAGEIFS(ASSESSMENTS!H:H,ASSESSMENTS!B:B,A6,ASSESSMENTS!E:E,"Mathematics"),1),"")) -> 60.9 | G6: =IF(A6="","",IFERROR(ROUND(AVERAGEIFS(ASSESSMENTS!H:H,ASSESSMENTS!B:B,A6,ASSESSMENTS!E:E,"Mathematical Literacy"),1),"")) | H6: =IF(A6="","",IFERROR(ROUND(AVERAGEIFS(ASSESSMENTS!H:H,ASSESSMENTS!B:B,A6,ASSESSMENTS!E:E,"Physical Sciences"),1),"")) | I6: =IF(A6="","",IFERROR(ROUND(AVERAGEIFS(ASSESSMENTS!H:H,ASSESSMENTS!B:B,A6,ASSESSMENTS!E:E,"Geography"),1),"")) | J6: =IF(A6="","",IFERROR(ROUND(AVERAGEIFS(ASSESSMENTS!H:H,ASSESSMENTS!B:B,A6,ASSESSMENTS!E:E,"Accounting"),1),"")) | K6: =IF(A6="","",IFERROR(ROUND(AVERAGEIFS(ASSESSMENTS!H:H,ASSESSMENTS!B:B,A6,ASSESSMENTS!E:E,"English"),1),"")) -> 52.4 | L6: =IF(A6="","",IFERROR(INDEX(ATTENDANCE_SUMMARY!G:G,MATCH(A6,ATTENDANCE_SUMMARY!A:A,0)),"")) -> 0.85416667 | M6: =IF(A6="","",IF(OR(E6<50,AND(L6<0.75,L6<>"" )),"At Risk","On Track")) -> On Track
A7: =IF(MASTER_REGISTER!E7="","",MASTER_REGISTER!E7) -> MSH202608006 | B7: =IF(A7="","",MASTER_REGISTER!F7) -> Karabo Ngobeni | C7: =IF(A7="","",MASTER_REGISTER!C7) -> 8 | D7: =IF(A7="","",COUNTIF(ASSESSMENTS!B:B,A7)) -> 10 | E7: =IF(D7=0,"",ROUND(AVERAGEIF(ASSESSMENTS!B:B,A7,ASSESSMENTS!H:H),1)) -> 67.7 | F7: =IF(A7="","",IFERROR(ROUND(AVERAGEIFS(ASSESSMENTS!H:H,ASSESSMENTS!B:B,A7,ASSESSMENTS!E:E,"Mathematics"),1),"")) -> 65 | G7: =IF(A7="","",IFERROR(ROUND(AVERAGEIFS(ASSESSMENTS!H:H,ASSESSMENTS!B:B,A7,ASSESSMENTS!E:E,"Mathematical Literacy"),1),"")) | H7: =IF(A7="","",IFERROR(ROUND(AVERAGEIFS(ASSESSMENTS!H:H,ASSESSMENTS!B:B,A7,ASSESSMENTS!E:E,"Physical Sciences"),1),"")) | I7: =IF(A7="","",IFERROR(ROUND(AVERAGEIFS(ASSESSMENTS!H:H,ASSESSMENTS!B:B,A7,ASSESSMENTS!E:E,"Geography"),1),"")) | J7: =IF(A7="","",IFERROR(ROUND(AVERAGEIFS(ASSESSMENTS!H:H,ASSESSMENTS!B:B,A7,ASSESSMENTS!E:E,"Accounting"),1),"")) | K7: =IF(A7="","",IFERROR(ROUND(AVERAGEIFS(ASSESSMENTS!H:H,ASSESSMENTS!B:B,A7,ASSESSMENTS!E:E,"English"),1),"")) -> 61.4 | L7: =IF(A7="","",IFERROR(INDEX(ATTENDANCE_SUMMARY!G:G,MATCH(A7,ATTENDANCE_SUMMARY!A:A,0)),"")) -> 0.875 | M7: =IF(A7="","",IF(OR(E7<50,AND(L7<0.75,L7<>"" )),"At Risk","On Track")) -> On Track
A8: =IF(MASTER_REGISTER!E8="","",MASTER_REGISTER!E8) -> MSH202608007 | B8: =IF(A8="","",MASTER_REGISTER!F8) -> Mpho Sithole | C8: =IF(A8="","",MASTER_REGISTER!C8) -> 8 | D8: =IF(A8="","",COUNTIF(ASSESSMENTS!B:B,A8)) -> 10 | E8: =IF(D8=0,"",ROUND(AVERAGEIF(ASSESSMENTS!B:B,A8,ASSESSMENTS!H:H),1)) -> 68.3 | F8: =IF(A8="","",IFERROR(ROUND(AVERAGEIFS(ASSESSMENTS!H:H,ASSESSMENTS!B:B,A8,ASSESSMENTS!E:E,"Mathematics"),1),"")) -> 70.4 | G8: =IF(A8="","",IFERROR(ROUND(AVERAGEIFS(ASSESSMENTS!H:H,ASSESSMENTS!B:B,A8,ASSESSMENTS!E:E,"Mathematical Literacy"),1),"")) | H8: =IF(A8="","",IFERROR(ROUND(AVERAGEIFS(ASSESSMENTS!H:H,ASSESSMENTS!B:B,A8,ASSESSMENTS!E:E,"Physical Sciences"),1),"")) | I8: =IF(A8="","",IFERROR(ROUND(AVERAGEIFS(ASSESSMENTS!H:H,ASSESSMENTS!B:B,A8,ASSESSMENTS!E:E,"Geography"),1),"")) | J8: =IF(A8="","",IFERROR(ROUND(AVERAGEIFS(ASSESSMENTS!H:H,ASSESSMENTS!B:B,A8,ASSESSMENTS!E:E,"Accounting"),1),"")) | K8: =IF(A8="","",IFERROR(ROUND(AVERAGEIFS(ASSESSMENTS!H:H,ASSESSMENTS!B:B,A8,ASSESSMENTS!E:E,"English"),1),"")) -> 51.5 | L8: =IF(A8="","",IFERROR(INDEX(ATTENDANCE_SUMMARY!G:G,MATCH(A8,ATTENDANCE_SUMMARY!A:A,0)),"")) -> 0.91666667 | M8: =IF(A8="","",IF(OR(E8<50,AND(L8<0.75,L8<>"" )),"At Risk","On Track")) -> On Track
A9: =IF(MASTER_REGISTER!E9="","",MASTER_REGISTER!E9) -> MSH202608008 | B9: =IF(A9="","",MASTER_REGISTER!F9) -> Tshepo Ramushu | C9: =IF(A9="","",MASTER_REGISTER!C9) -> 8 | D9: =IF(A9="","",COUNTIF(ASSESSMENTS!B:B,A9)) -> 10 | E9: =IF(D9=0,"",ROUND(AVERAGEIF(ASSESSMENTS!B:B,A9,ASSESSMENTS!H:H),1)) -> 64.4 | F9: =IF(A9="","",IFERROR(ROUND(AVERAGEIFS(ASSESSMENTS!H:H,ASSESSMENTS!B:B,A9,ASSESSMENTS!E:E,"Mathematics"),1),"")) -> 72 | G9: =IF(A9="","",IFERROR(ROUND(AVERAGEIFS(ASSESSMENTS!H:H,ASSESSMENTS!B:B,A9,ASSESSMENTS!E:E,"Mathematical Literacy"),1),"")) | H9: =IF(A9="","",IFERROR(ROUND(AVERAGEIFS(ASSESSMENTS!H:H,ASSESSMENTS!B:B,A9,ASSESSMENTS!E:E,"Physical Sciences"),1),"")) | I9: =IF(A9="","",IFERROR(ROUND(AVERAGEIFS(ASSESSMENTS!H:H,ASSESSMENTS!B:B,A9,ASSESSMENTS!E:E,"Geography"),1),"")) | J9: =IF(A9="","",IFERROR(ROUND(AVERAGEIFS(ASSESSMENTS!H:H,ASSESSMENTS!B:B,A9,ASSESSMENTS!E:E,"Accounting"),1),"")) | K9: =IF(A9="","",IFERROR(ROUND(AVERAGEIFS(ASSESSMENTS!H:H,ASSESSMENTS!B:B,A9,ASSESSMENTS!E:E,"English"),1),"")) -> 53.2 | L9: =IF(A9="","",IFERROR(INDEX(ATTENDANCE_SUMMARY!G:G,MATCH(A9,ATTENDANCE_SUMMARY!A:A,0)),"")) -> 0.875 | M9: =IF(A9="","",IF(OR(E9<50,AND(L9<0.75,L9<>"" )),"At Risk","On Track")) -> On Track
